Workbook

Sheet Data w Labels
B2: CONCEPTS | E2: TIME SLOTS
B4: Assigned # | C4: Concept | E4: Assigned # | F4: Time Slot (PST) Start | G4: Time Slot (PST) End
B5: 1 | C5: Desktop + Gaming | E5: Early asf | F5: 0.33333333 | G5: 0.45763889
B6: 2 | C6: Collab | E6: Great times | F6: 0.45833333 | G6: 0.58263889
B7: 3 | C7: IRL | E7: Prime hours | F7: 0.58333333 | G7: 0.70763889
B8: 4 | C8: Barky | E8: Good times | F8: 0.70833333 | G8: 0.83263889
B9: 5 | C9: OSCS balesh | E9: Late-night | F9: 0.83333333 | G9: 0.91597222
B10: 6 | C10: Rizz | E10: GG est mfs | F10: 0.91666667 | G10: 0.99930556
B11: 7 | C11: Events | E11: Lol | F11: 0 | G11: 0.082638889
B12: 8 | C12: Travels | E12: KeYS | F12: 0.083333333 | G12: 0.33263889
B17: STREAM INPUTS
B19: Date | C19: Stream | D19: Concept | E19: Avg Viewers | F19: Max Viewers | G19: Followers Gained | H19: Hrs Streamed | I19: Start time (PST) | J19: Time Slot
B20: 45967 | C20: Desktop | D20: 1 | E20: 3296 | F20: 3808 | G20: 293 | H20: 6.3 | I20: 0.82847222 | J20: {=_xlfn.IFS(AND(DATA[[#This Row],[Start time (PST)]]>=$F$5,DATA[[#This Row],[Start time (PST)]]<=$G$5),"Early asf",AND(DATA[[#This Row],[Start time (PST)]]>=$F$6,DATA[[#This Row],[Start time (PST)]]<=$G$6),"Great times",AND(DATA[[#This Row],[Start time (PST)]]>=$F$7,DATA[[#This Row],[Start time (PST)]]<=$G$7),"Prime hours",AND(DATA[[#This Row],[Start time (PST)]]>=$F$8,DATA[[#This Row],[Start time (PST)]]<=$G$8),"Good times",AND(DATA[[#This Row],[Start time (PST)]]>=$F$9,DATA[[#This Row],[Start time (PST)]]<=$G$9),"Late-night",AND(DATA[[#This Row],[Start time (PST)]]>=$F$10,DATA[[#This Row],[Start time (PST)]]<=$G$10),"GG EST mfs",AND(DATA[[#This Row],[Start time (PST)]]>=$F$11,DATA[[#This Row],[Start time (PST)]]<=$G$11),"Lol",AND(DATA[[#This Row],[Start time (PST)]]>=$F$12,DATA[[#This Row],[Start time (PST)]]<=$G$12),"KeYS")} -> Good times
B21: 45968 | C21: ATL w AMP | D21: 2 | E21: 3532 | F21: 4734 | G21: 433 | H21: 5.4 | I21: 0.70069444 | J21: {=_xlfn.IFS(AND(DATA[[#This Row],[Start time (PST)]]>=$F$5,DATA[[#This Row],[Start time (PST)]]<=$G$5),"Early asf",AND(DATA[[#This Row],[Start time (PST)]]>=$F$6,DATA[[#This Row],[Start time (PST)]]<=$G$6),"Great times",AND(DATA[[#This Row],[Start time (PST)]]>=$F$7,DATA[[#This Row],[Start time (PST)]]<=$G$7),"Prime hours",AND(DATA[[#This Row],[Start time (PST)]]>=$F$8,DATA[[#This Row],[Start time (PST)]]<=$G$8),"Good times",AND(DATA[[#This Row],[Start time (PST)]]>=$F$9,DATA[[#This Row],[Start time (PST)]]<=$G$9),"Late-night",AND(DATA[[#This Row],[Start time (PST)]]>=$F$10,DATA[[#This Row],[Start time (PST)]]<=$G$10),"GG EST mfs",AND(DATA[[#This Row],[Start time (PST)]]>=$F$11,DATA[[#This Row],[Start time (PST)]]<=$G$11),"Lol",AND(DATA[[#This Row],[Start time (PST)]]>=$F$12,DATA[[#This Row],[Start time (PST)]]<=$G$12),"KeYS")} -> Prime hours
B22: 45969 | C22: ATL w Clovaaaaa | D22: 2 | E22: 3297 | F22: 4237 | G22: 434 | H22: 6.8 | I22: 0.72847222 | J22: {=_xlfn.IFS(AND(DATA[[#This Row],[Start time (PST)]]>=$F$5,DATA[[#This Row],[Start time (PST)]]<=$G$5),"Early asf",AND(DATA[[#This Row],[Start time (PST)]]>=$F$6,DATA[[#This Row],[Start time (PST)]]<=$G$6),"Great times",AND(DATA[[#This Row],[Start time (PST)]]>=$F$7,DATA[[#This Row],[Start time (PST)]]<=$G$7),"Prime hours",AND(DATA[[#This Row],[Start time (PST)]]>=$F$8,DATA[[#This Row],[Start time (PST)]]<=$G$8),"Good times",AND(DATA[[#This Row],[Start time (PST)]]>=$F$9,DATA[[#This Row],[Start time (PST)]]<=$G$9),"Late-night",AND(DATA[[#This Row],[Start time (PST)]]>=$F$10,DATA[[#This Row],[Start time (PST)]]<=$G$10),"GG EST mfs",AND(DATA[[#This Row],[Start time (PST)]]>=$F$11,DATA[[#This Row],[Start time (PST)]]<=$G$11),"Lol",AND(DATA[[#This Row],[Start time (PST)]]>=$F$12,DATA[[#This Row],[Start time (PST)]]<=$G$12),"KeYS")} -> Good times
B23: 45971 | C23: Matcha Monday w Jake | D23: 2 | E23: 3604 | F23: 4505 | G23: 621 | H23: 14.9 | I23: 0.50138889 | J23: {=_xlfn.IFS(AND(DATA[[#This Row],[Start time (PST)]]>=$F$5,DATA[[#This Row],[Start time (PST)]]<=$G$5),"Early asf",AND(DATA[[#This Row],[Start time (PST)]]>=$F$6,DATA[[#This Row],[Start time (PST)]]<=$G$6),"Great times",AND(DATA[[#This Row],[Start time (PST)]]>=$F$7,DATA[[#This Row],[Start time (PST)]]<=$G$7),"Prime hours",AND(DATA[[#This Row],[Start time (PST)]]>=$F$8,DATA[[#This Row],[Start time (PST)]]<=$G$8),"Good times",AND(DATA[[#This Row],[Start time (PST)]]>=$F$9,DATA[[#This Row],[Start time (PST)]]<=$G$9),"Late-night",AND(DATA[[#This Row],[Start time (PST)]]>=$F$10,DATA[[#This Row],[Start time (PST)]]<=$G$10),"GG EST mfs",AND(DATA[[#This Row],[Start time (PST)]]>=$F$11,DATA[[#This Row],[Start time (PST)]]<=$G$11),"Lol",AND(DATA[[#This Row],[Start time (PST)]]>=$F$12,DATA[[#This Row],[Start time (PST)]]<=$G$12),"KeYS")} -> Great times
B24: 45972 | C24: Buying temu motorcycle | D24: 5 | E24: 5557 | F24: 9005 | G24: 524 | H24: 9.2 | I24: 0.71805556 | J24: {=_xlfn.IFS(AND(DATA[[#This Row],[Start time (PST)]]>=$F$5,DATA[[#This Row],[Start time (PST)]]<=$G$5),"Early asf",AND(DATA[[#This Row],[Start time (PST)]]>=$F$6,DATA[[#This Row],[Start time (PST)]]<=$G$6),"Great times",AND(DATA[[#This Row],[Start time (PST)]]>=$F$7,DATA[[#This Row],[Start time (PST)]]<=$G$7),"Prime hours",AND(DATA[[#This Row],[Start time (PST)]]>=$F$8,DATA[[#This Row],[Start time (PST)]]<=$G$8),"Good times",AND(DATA[[#This Row],[Start time (PST)]]>=$F$9,DATA[[#This Row],[Start time (PST)]]<=$G$9),"Late-night",AND(DATA[[#This Row],[Start time (PST)]]>=$F$10,DATA[[#This Row],[Start time (PST)]]<=$G$10),"GG EST mfs",AND(DATA[[#This Row],[Start time (PST)]]>=$F$11,DATA[[#This Row],[Start time (PST)]]<=$G$11),"Lol",AND(DATA[[#This Row],[Start time (PST)]]>=$F$12,DATA[[#This Row],[Start time (PST)]]<=$G$12),"KeYS")} -> Good times
B25: 45973 | C25: Sisathon + Barky | D25: 4 | E25: 3918 | F25: 7881 | G25: 801 | H25: 12.2 | I25: 0.71180556 | J25: {=_xlfn.IFS(AND(DATA[[#This Row],[Start time (PST)]]>=$F$5,DATA[[#This Row],[Start time (PST)]]<=$G$5),"Early asf",AND(DATA[[#This Row],[Start time (PST)]]>=$F$6,DATA[[#This Row],[Start time (PST)]]<=$G$6),"Great times",AND(DATA[[#This Row],[Start time (PST)]]>=$F$7,DATA[[#This Row],[Start time (PST)]]<=$G$7),"Prime hours",AND(DATA[[#This Row],[Start time (PST)]]>=$F$8,DATA[[#This Row],[Start time (PST)]]<=$G$8),"Good times",AND(DATA[[#This Row],[Start time (PST)]]>=$F$9,DATA[[#This Row],[Start time (PST)]]<=$G$9),"Late-night",AND(DATA[[#This Row],[Start time (PST)]]>=$F$10,DATA[[#This Row],[Start time (PST)]]<=$G$10),"GG EST mfs",AND(DATA[[#This Row],[Start time (PST)]]>=$F$11,DATA[[#This Row],[Start time (PST)]]<=$G$11),"Lol",AND(DATA[[#This Row],[Start time (PST)]]>=$F$12,DATA[[#This Row],[Start time (PST)]]<=$G$12),"KeYS")} -> Good times
B26: 45974 | C26: Sisathon party | D26: 3 | E26: 4302 | F26: 5867 | G26: 609 | H26: 7.4 | I26: 0.87638889 | J26: {=_xlfn.IFS(AND(DATA[[#This Row],[Start time (PST)]]>=$F$5,DATA[[#This Row],[Start time (PST)]]<=$G$5),"Early asf",AND(DATA[[#This Row],[Start time (PST)]]>=$F$6,DATA[[#This Row],[Start time (PST)]]<=$G$6),"Great times",AND(DATA[[#This Row],[Start time (PST)]]>=$F$7,DATA[[#This Row],[Start time (PST)]]<=$G$7),"Prime hours",AND(DATA[[#This Row],[Start time (PST)]]>=$F$8,DATA[[#This Row],[Start time (PST)]]<=$G$8),"Good times",AND(DATA[[#This Row],[Start time (PST)]]>=$F$9,DATA[[#This Row],[Start time (PST)]]<=$G$9),"Late-night",AND(DATA[[#This Row],[Start time (PST)]]>=$F$10,DATA[[#This Row],[Start time (PST)]]<=$G$10),"GG EST mfs",AND(DATA[[#This Row],[Start time (PST)]]>=$F$11,DATA[[#This Row],[Start time (PST)]]<=$G$11),"Lol",AND(DATA[[#This Row],[Start time (PST)]]>=$F$12,DATA[[#This Row],[Start time (PST)]]<=$G$12),"KeYS")} -> Late-night
B27: 45975 | C27: OSCS paintball | D27: 5 | E27: 2420 | F27: 3161 | G27: 239 | H27: 2.6 | I27: 0.61458333 | J27: {=_xlfn.IFS(AND(DATA[[#This Row],[Start time (PST)]]>=$F$5,DATA[[#This Row],[Start time (PST)]]<=$G$5),"Early asf",AND(DATA[[#This Row],[Start time (PST)]]>=$F$6,DATA[[#This Row],[Start time (PST)]]<=$G$6),"Great times",AND(DATA[[#This Row],[Start time (PST)]]>=$F$7,DATA[[#This Row],[Start time (PST)]]<=$G$7),"Prime hours",AND(DATA[[#This Row],[Start time (PST)]]>=$F$8,DATA[[#This Row],[Start time (PST)]]<=$G$8),"Good times",AND(DATA[[#This Row],[Start time (PST)]]>=$F$9,DATA[[#This Row],[Start time (PST)]]<=$G$9),"Late-night",AND(DATA[[#This Row],[Start time (PST)]]>=$F$10,DATA[[#This Row],[Start time (PST)]]<=$G$10),"GG EST mfs",AND(DATA[[#This Row],[Start time (PST)]]>=$F$11,DATA[[#This Row],[Start time (PST)]]<=$G$11),"Lol",AND(DATA[[#This Row],[Start time (PST)]]>=$F$12,DATA[[#This Row],[Start time (PST)]]<=$G$12),"KeYS")} -> Prime hours
B28: 45976 | C28: Baking & painting w Maru | D28: 6 | E28: 5387 | F28: 6738 | G28: 534 | H28: 4.9 | I28: 0.7625 | J28: {=_xlfn.IFS(AND(DATA[[#This Row],[Start time (PST)]]>=$F$5,DATA[[#This Row],[Start time (PST)]]<=$G$5),"Early asf",AND(DATA[[#This Row],[Start time (PST)]]>=$F$6,DATA[[#This Row],[Start time (PST)]]<=$G$6),"Great times",AND(DATA[[#This Row],[Start time (PST)]]>=$F$7,DATA[[#This Row],[Start time (PST)]]<=$G$7),"Prime hours",AND(DATA[[#This Row],[Start time (PST)]]>=$F$8,DATA[[#This Row],[Start time (PST)]]<=$G$8),"Good times",AND(DATA[[#This Row],[Start time (PST)]]>=$F$9,DATA[[#This Row],[Start time (PST)]]<=$G$9),"Late-night",AND(DATA[[#This Row],[Start time (PST)]]>=$F$10,DATA[[#This Row],[Start time (PST)]]<=$G$10),"GG EST mfs",AND(DATA[[#This Row],[Start time (PST)]]>=$F$11,DATA[[#This Row],[Start time (PST)]]<=$G$11),"Lol",AND(DATA[[#This Row],[Start time (PST)]]>=$F$12,DATA[[#This Row],[Start time (PST)]]<=$G$12),"KeYS")} -> Good times
B29: 45977 | C29: Streamer awards nominations | D29: 1 | E29: 3922 | F29: 8648 | G29: 528 | H29: 3.9 | I29: 0.5 | J29: {=_xlfn.IFS(AND(DATA[[#This Row],[Start time (PST)]]>=$F$5,DATA[[#This Row],[Start time (PST)]]<=$G$5),"Early asf",AND(DATA[[#This Row],[Start time (PST)]]>=$F$6,DATA[[#This Row],[Start time (PST)]]<=$G$6),"Great times",AND(DATA[[#This Row],[Start time (PST)]]>=$F$7,DATA[[#This Row],[Start time (PST)]]<=$G$7),"Prime hours",AND(DATA[[#This Row],[Start time (PST)]]>=$F$8,DATA[[#This Row],[Start time (PST)]]<=$G$8),"Good times",AND(DATA[[#This Row],[Start time (PST)]]>=$F$9,DATA[[#This Row],[Start time (PST)]]<=$G$9),"Late-night",AND(DATA[[#This Row],[Start time (PST)]]>=$F$10,DATA[[#This Row],[Start time (PST)]]<=$G$10),"GG EST mfs",AND(DATA[[#This Row],[Start time (PST)]]>=$F$11,DATA[[#This Row],[Start time (PST)]]<=$G$11),"Lol",AND(DATA[[#This Row],[Start time (PST)]]>=$F$12,DATA[[#This Row],[Start time (PST)]]<=$G$12),"KeYS")} -> Great times
B30: 45978 | C30: Desktop + MRE mukbang | D30: 5 | E30: 4468 | F30: 6084 | G30: 769 | H30: 9.9 | I30: 0.575 | J30: {=_xlfn.IFS(AND(DATA[[#This Row],[Start time (PST)]]>=$F$5,DATA[[#This Row],[Start time (PST)]]<=$G$5),"Early asf",AND(DATA[[#This Row],[Start time (PST)]]>=$F$6,DATA[[#This Row],[Start time (PST)]]<=$G$6),"Great times",AND(DATA[[#This Row],[Start time (PST)]]>=$F$7,DATA[[#This Row],[Start time (PST)]]<=$G$7),"Prime hours",AND(DATA[[#This Row],[Start time (PST)]]>=$F$8,DATA[[#This Row],[Start time (PST)]]<=$G$8),"Good times",AND(DATA[[#This Row],[Start time (PST)]]>=$F$9,DATA[[#This Row],[Start time (PST)]]<=$G$9),"Late-night",AND(DATA[[#This Row],[Start time (PST)]]>=$F$10,DATA[[#This Row],[Start time (PST)]]<=$G$10),"GG EST mfs",AND(DATA[[#This Row],[Start time (PST)]]>=$F$11,DATA[[#This Row],[Start time (PST)]]<=$G$11),"Lol",AND(DATA[[#This Row],[Start time (PST)]]>=$F$12,DATA[[#This Row],[Start time (PST)]]<=$G$12),"KeYS")} -> Great times
B31: 45979 | C31: Triple Threat gaming | D31: 1 | E31: 3496 | F31: 7090 | G31: 521 | H31: 10.1 | I31: 0.85416667 | J31: {=_xlfn.IFS(AND(DATA[[#This Row],[Start time (PST)]]>=$F$5,DATA[[#This Row],[Start time (PST)]]<=$G$5),"Early asf",AND(DATA[[#This Row],[Start time (PST)]]>=$F$6,DATA[[#This Row],[Start time (PST)]]<=$G$6),"Great times",AND(DATA[[#This Row],[Start time (PST)]]>=$F$7,DATA[[#This Row],[Start time (PST)]]<=$G$7),"Prime hours",AND(DATA[[#This Row],[Start time (PST)]]>=$F$8,DATA[[#This Row],[Start time (PST)]]<=$G$8),"Good times",AND(DATA[[#This Row],[Start time (PST)]]>=$F$9,DATA[[#This Row],[Start time (PST)]]<=$G$9),"Late-night",AND(DATA[[#This Row],[Start time (PST)]]>=$F$10,DATA[[#This Row],[Start time (PST)]]<=$G$10),"GG EST mfs",AND(DATA[[#This Row],[Start time (PST)]]>=$F$11,DATA[[#This Row],[Start time (PST)]]<=$G$11),"Lol",AND(DATA[[#This Row],[Start time (PST)]]>=$F$12,DATA[[#This Row],[Start time (PST)]]<=$G$12),"KeYS")} -> Late-night
... B147: 46144 | C147: Toronto debrief | D147: 1 | E147: 12436 | F147: 16928 | G147: 573 | H147: 2.7 | I147: 0.52361111 | J147: {=_xlfn.IFS(AND(DATA[[#This Row],[Start time (PST)]]>=$F$5,DATA[[#This Row],[Start time (PST)]]<=$G$5),"Early asf",AND(DATA[[#This Row],[Start time (PST)]]>=$F$6,DATA[[#This Row],[Start time (PST)]]<=$G$6),"Great times",AND(DATA[[#This Row],[Start time (PST)]]>=$F$7,DATA[[#This Row],[Start time (PST)]]<=$G$7),"Prime hours",AND(DATA[[#This Row],[Start time (PST)]]>=$F$8,DATA[[#This Row],[Start time (PST)]]<=$G$8),"Good times",AND(DATA[[#This Row],[Start time (PST)]]>=$F$9,DATA[[#This Row],[Start time (PST)]]<=$G$9),"Late-night",AND(DATA[[#This Row],[Start time (PST)]]>=$F$10,DATA[[#This Row],[Start time (PST)]]<=$G$10),"GG EST mfs",AND(DATA[[#This Row],[Start time (PST)]]>=$F$11,DATA[[#This Row],[Start time (PST)]]<=$G$11),"Lol",AND(DATA[[#This Row],[Start time (PST)]]>=$F$12,DATA[[#This Row],[Start time (PST)]]<=$G$12),"KeYS")} -> Great times

Sheet Concept(s) Analysis Breakdown
B3: Desktop + Gaming Data | S3: Collabs | AJ3: IRL | BA3: BARKY | BR3: OSCS balesh | CI3: Rizz | CZ3: Events | DQ3: Travels
B5: Date | C5: Stream | D5: Concept | E5: Avg Viewers | F5: Max Viewers | G5: Followers Gained | H5: Hrs Streamed | I5: Start time (PST) | J5: Time Slot | S5: Date | T5: Stream | U5: Concept | V5: Avg Viewers | W5: Max Viewers | X5: Followers Gained | Y5: Hrs Streamed | Z5: Start time (PST) | AA5: Time Slot | AJ5: Date | AK5: Stream | AL5: Concept | AM5: Avg Viewers | AN5: Max Viewers | AO5: Followers Gained | AP5: Hrs Streamed | AQ5: Start time (PST) | AR5: Time Slot | BA5: Date | BB5: Stream | BC5: Concept | BD5: Avg Viewers | BE5: Max Viewers | BF5: Followers Gained | BG5: Hrs Streamed | BH5: Start time (PST) | BI5: Time Slot | BR5: Date | BS5: Stream | BT5: Concept | BU5: Avg Viewers | BV5: Max Viewers | BW5: Followers Gained | BX5: Hrs Streamed | BY5: Start time (PST) | BZ5: Time Slot | CI5: Date | CJ5: Stream | CK5: Concept | CL5: Avg Viewers | CM5: Max Viewers | CN5: Followers Gained | CO5: Hrs Streamed | CP5: Start time (PST) | CQ5: Time Slot | CZ5: Date | DA5: Stream | DB5: Concept | DC5: Avg Viewers | DD5: Max Viewers | DE5: Followers Gained | DF5: Hrs Streamed | DG5: Start time (PST) | DH5: Time Slot | DQ5: Date | DR5: Stream | DS5: Concept | DT5: Avg Viewers | DU5: Max Viewers | DV5: Followers Gained | DW5: Hrs Streamed | DX5: Start time (PST) | DY5: Time Slot
B6: {=_xlfn._xlws.FILTER(DATA[],DATA[Concept]=1,0)} -> 45967 | C6: Desktop | D6: 1 | E6: 3296 | F6: 3808 | G6: 293 | H6: 6.3 | I6: 0.82847222 | J6: Good times | K6: =E6 -> 3296 | S6: {=_xlfn._xlws.FILTER(DATA[],DATA[Concept]=2,0)} -> 45968 | T6: ATL w AMP | U6: 2 | V6: 3532 | W6: 4734 | X6: 433 | Y6: 5.4 | Z6: 0.70069444 | AA6: Prime hours | AJ6: {=_xlfn._xlws.FILTER(DATA[],DATA[Concept]=3,0)} -> 45974 | AK6: Sisathon party | AL6: 3 | AM6: 4302 | AN6: 5867 | AO6: 609 | AP6: 7.4 | AQ6: 0.87638889 | AR6: Late-night | BA6: {=_xlfn._xlws.FILTER(DATA[],DATA[Concept]=4,0)} -> 45973 | BB6: Sisathon + Barky | BC6: 4 | BD6: 3918 | BE6: 7881 | BF6: 801 | BG6: 12.2 | BH6: 0.71180556 | BI6: Good times | BR6: {=_xlfn._xlws.FILTER(DATA[],DATA[Concept]=5,0)} -> 45972 | BS6: Buying temu motorcycle | BT6: 5 | BU6: 5557 | BV6: 9005 | BW6: 524 | BX6: 9.2 | BY6: 0.71805556 | BZ6: Good times | CI6: {=_xlfn._xlws.FILTER(DATA[],DATA[Concept]=6,0)} -> 45976 | CJ6: Baking & painting w Maru | CK6: 6 | CL6: 5387 | CM6: 6738 | CN6: 534 | CO6: 4.9 | CP6: 0.7625 | CQ6: Good times | CZ6: {=_xlfn._xlws.FILTER(DATA[],DATA[Concept]=7,0)} -> 45997 | DA6: Streamer awards | DB6: 7 | DC6: 2987 | DD6: 6110 | DE6: 387 | DF6: 2.1 | DG6: 0.65069444 | DH6: Prime hours | DQ6: {=_xlfn._xlws.FILTER(DATA[],DATA[Concept]=8,0)} -> 46083 | DR6: India, lost in | DS6: 8 | DT6: 6357 | DU6: 8022 | DV6: 921 | DW6: 6 | DX6: 0.85555556 | DY6: Late-night
B7: 45977 | C7: Streamer awards nominations | D7: 1 | E7: 3922 | F7: 8648 | G7: 528 | H7: 3.9 | I7: 0.5 | J7: Great times | K7: =E7 -> 3922 | O7: % WT | P7: Avg Viewers | Q7: Avg FG / stream | S7: 45969 | T7: ATL w Clovaaaaa | U7: 2 | V7: 3297 | W7: 4237 | X7: 434 | Y7: 6.8 | Z7: 0.72847222 | AA7: Good times | AF7: % WT | AG7: Avg Viewers | AH7: Avg FG / stream | AJ7: 45981 | AK7: Science experiments | AL7: 3 | AM7: 3596 | AN7: 4158 | AO7: 98 | AP7: 1.5 | AQ7: 0.81458333 | AR7: Good times | AW7: % WT | AX7: Avg Viewers | AY7: Avg FG / stream | BA7: 46010 | BB7: Laxative escape room + barky | BC7: 4 | BD7: 7345 | BE7: 11817 | BF7: 807 | BG7: 9.7 | BH7: 0.69583333 | BI7: Prime hours | BN7: % WT | BO7: Avg Viewers | BP7: Avg FG / stream | BR7: 45975 | BS7: OSCS paintball | BT7: 5 | BU7: 2420 | BV7: 3161 | BW7: 239 | BX7: 2.6 | BY7: 0.61458333 | BZ7: Prime hours | CE7: % WT | CF7: Avg Viewers | CG7: Avg FG / stream | CI7: 46000 | CJ7: OSCS Lake Tahoe roadtrip | CK7: 6 | CL7: 5596 | CM7: 7642 | CN7: 1279 | CO7: 13.7 | CP7: 0.65347222 | CQ7: Prime hours | CV7: % WT | CW7: Avg Viewers | CX7: Avg FG / stream | CZ7: 46012 | DA7: QT Concert | DB7: 7 | DC7: 6643 | DD7: 11966 | DE7: 655 | DF7: 9.9 | DG7: 0.68194444 | DH7: Prime hours | DM7: % WT | DN7: Avg Viewers | DO7: Avg FG / stream | DQ7: 46084 | DR7: India, holi festival | DS7: 8 | DT7: 5671 | DU7: 7400 | DV7: 628 | DW7: 6.1 | DX7: 0.95763889 | DY7: GG EST mfs | ED7: % WT | EE7: Avg Viewers | EF7: Avg FG / stream
B8: 45979 | C8: Triple Threat gaming | D8: 1 | E8: 3496 | F8: 7090 | G8: 521 | H8: 10.1 | I8: 0.85416667 | J8: Late-night | K8: =E8 -> 3496 | L8: Avg Viewers | M8: =AVERAGE(E6:E1048576) -> 5373.3125 | N8: Prime hours | O8: {=SUM(IF($J$6:$J$1340=N8,(($H$6:$H$1340)),0))/$M$12} -> 0.1744373 | P8: {=SUM(IF($J$6:$J$1340=N8,($E$6:$E$1340),0))/SUM(IF($J$6:$J$1340=N8,1,0))} -> 6507 | Q8: {=SUM(IF($J$6:$J$1340=N8,($G$6:$G$1340),0))/SUM(IF($J$6:$J$1340=N8,1,0))} -> 868.5 | S8: 45971 | T8: Matcha Monday w Jake | U8: 2 | V8: 3604 | W8: 4505 | X8: 621 | Y8: 14.9 | Z8: 0.50138889 | AA8: Great times | AC8: Avg Viewers | AD8: =AVERAGE(V6:V1048576) -> 5015.5588 | AE8: Prime hours | AF8: {=SUM(IF($AA$6:$AA$1340=AE8,(($Y$6:$Y$1340)),0))/$AD$12} -> 0.34111045 | AG8: {=SUM(IF($AA$6:$AA$1340=AE8,($V$6:$V$1340),0))/SUM(IF($AA$6:$AA$1340=AE8,1,0))} -> 4648.0833 | AH8: {=SUM(IF($AA$6:$AA$1340=AE8,($X$6:$X$1340),0))/SUM(IF($AA$6:$AA$1340=AE8,1,0))} -> 589.66667 | AJ8: 45982 | AK8: Lost in LV | AL8: 3 | AM8: 4810 | AN8: 7628 | AO8: 506 | AP8: 6.4 | AQ8: 0.71041667 | AR8: Good times | AT8: Avg Viewers | AU8: =AVERAGE(AM6:AM1048576) -> 5007 | AV8: Prime hours | AW8: {=SUM(IF($AR$6:$AR$1340=AV8,(($AP$6:$AP$1340)),0))/$AU$12} -> 0.45371143 | AX8: {=SUM(IF($AR$6:$AR$1340=AV8,($AM$6:$AM$1340),0))/SUM(IF($AR$6:$AR$1340=AV8,1,0))} -> 4553 | AY8: {=SUM(IF($AR$6:$AR$1340=AV8,($AO$6:$AO$1340),0))/SUM(IF($AR$6:$AR$1340=AV8,1,0))} -> 397.83333 | BA8: 46014 | BB8: Bonnie guess & donates | BC8: 4 | BD8: 12243 | BE8: 17633 | BF8: 1245 | BG8: 7.6 | BH8: 0.575 | BI8: Great times | BK8: Avg Viewers | BL8: =AVERAGE(BD6:BD1048576) -> 8094.3846 | BM8: Prime hours | BN8: {=SUM(IF($BI$6:$BI$1340=BM8,(($BG$6:$BG$1340)),0))/$BL$12} -> 0.12188612 | BO8: {=SUM(IF($BI$6:$BI$1340=BM8,($BD$6:$BD$1340),0))/SUM(IF($BI$6:$BI$1340=BM8,1,0))} -> 7091.5 | BP8: {=SUM(IF($BI$6:$BI$1340=BM8,($BF$6:$BF$1340),0))/SUM(IF($BI$6:$BI$1340=BM8,1,0))} -> 660.5 | BR8: 45978 | BS8: Desktop + MRE mukbang | BT8: 5 | BU8: 4468 | BV8: 6084 | BW8: 769 | BX8: 9.9 | BY8: 0.575 | BZ8: Great times | CB8: Avg Viewers | CC8: =AVERAGE(BU6:BU1048576) -> 4942.2963 | CD8: Prime hours | CE8: {=SUM(IF($BZ$6:$BZ$1340=CD8,(($BX$6:$BX$1340)),0))/$CC$12} -> 0.3245614 | CF8: {=SUM(IF($BZ$6:$BZ$1340=CD8,($BU$6:$BU$1340),0))/SUM(IF($BZ$6:$BZ$1340=CD8,1,0))} -> 4467.75 | CG8: {=SUM(IF($BZ$6:$BZ$1340=CD8,($BW$6:$BW$1340),0))/SUM(IF($BZ$6:$BZ$1340=CD8,1,0))} -> 493.125 | CI8: 46001 | CJ8: OSCS Lake Tahoe | CK8: 6 | CL8: 5815 | CM8: 7846 | CN8: 749 | CO8: 10.8 | CP8: 0.72638889 | CQ8: Good times | CS8: Avg Viewers | CT8: =AVERAGE(CL6:CL1048576) -> 5911.2 | CU8: Prime hours | CV8: {=SUM(IF($CQ$6:$CQ$1340=CU8,(($CO$6:$CO$1340)),0))/$CT$12} -> 0.3010989 | CW8: {=SUM(IF($CQ$6:$CQ$1340=CU8,($CL$6:$CL$1340),0))/SUM(IF($CQ$6:$CQ$1340=CU8,1,0))} -> 5596 | CX8: {=SUM(IF($CQ$6:$CQ$1340=CU8,($CN$6:$CN$1340),0))/SUM(IF($CQ$6:$CQ$1340=CU8,1,0))} -> 1279 | CZ8: 46041 | DA8: Last to fall asleep | DB8: 7 | DC8: 6404 | DD8: 9394 | DE8: 631 | DF8: 10.5 | DG8: 0.78611111 | DH8: Good times | DJ8: Avg Viewers | DK8: =AVERAGE(DC6:DC1048576) -> 5212 | DL8: Prime hours | DM8: {=SUM(IF($DH$6:$DH$1340=DL8,(($DF$6:$DF$1340)),0))/$DK$12} -> 0.37521968 | DN8: {=SUM(IF($DH$6:$DH$1340=DL8,($DC$6:$DC$1340),0))/SUM(IF($DH$6:$DH$1340=DL8,1,0))} -> 5539.1667 | DO8: {=SUM(IF($DH$6:$DH$1340=DL8,($DE$6:$DE$1340),0))/SUM(IF($DH$6:$DH$1340=DL8,1,0))} -> 492.66667 | DQ8: 46085 | DR8: India, doug doug | DS8: 8 | DT8: 4134 | DU8: 5489 | DV8: 368 | DW8: 6.1 | DX8: 0.87291667 | DY8: Late-night | EA8: Avg Viewers | EB8: =AVERAGE(DT6:DT1048576) -> 4829.4 | EC8: Prime hours | ED8: {=SUM(IF($DY$6:$DY$1340=EC8,(($DW$6:$DW$1340)),0))/$EB$12} -> 0.47550432 | EE8: {=SUM(IF($DY$6:$DY$1340=EC8,($DT$6:$DT$1340),0))/SUM(IF($DY$6:$DY$1340=EC8,1,0))} -> 3992.5 | EF8: {=SUM(IF($DY$6:$DY$1340=EC8,($DV$6:$DV$1340),0))/SUM(IF($DY$6:$DY$1340=EC8,1,0))} -> 233.5
B9: 45992 | C9: Arkmas gaming | D9: 1 | E9: 3006 | F9: 4264 | G9: 338 | H9: 10 | I9: 0.73888889 | J9: Good times | K9: =E9 -> 3006 | L9: Avg Max Viewers | M9: =AVERAGE(F6:F1048576) -> 8598.0625 | N9: Great times | O9: {=SUM(IF($J$6:$J$1340=N9,(($H$6:$H$1340)),0))/$M$12} -> 0.15434084 | P9: {=SUM(IF($J$6:$J$1340=N9,($E$6:$E$1340),0))/SUM(IF($J$6:$J$1340=N9,1,0))} -> 7483 | Q9: {=SUM(IF($J$6:$J$1340=N9,($G$6:$G$1340),0))/SUM(IF($J$6:$J$1340=N9,1,0))} -> 549 | S9: 45987 | T9: Pilates + Thanksgiving FaZe cooking | U9: 2 | V9: 5500 | W9: 10079 | X9: 1191 | Y9: 11.5 | Z9: 0.51458333 | AA9: Great times | AC9: Avg Max Viewers | AD9: =AVERAGE(W6:W1048576) -> 7933.9118 | AE9: Great times | AF9: {=SUM(IF($AA$6:$AA$1340=AE9,(($Y$6:$Y$1340)),0))/$AD$12} -> 0.46544595 | AG9: {=SUM(IF($AA$6:$AA$1340=AE9,($V$6:$V$1340),0))/SUM(IF($AA$6:$AA$1340=AE9,1,0))} -> 5326.1429 | AH9: {=SUM(IF($AA$6:$AA$1340=AE9,($X$6:$X$1340),0))/SUM(IF($AA$6:$AA$1340=AE9,1,0))} -> 759.71429 | AJ9: 45985 | AK9: Extreme escape room | AL9: 3 | AM9: 4839 | AN9: 7731 | AO9: 541 | AP9: 7.7 | AQ9: 0.85763889 | AR9: Late-night | AT9: Avg Max Viewers | AU9: =AVERAGE(AN6:AN1048576) -> 7795.9286 | AV9: Great times | AW9: {=SUM(IF($AR$6:$AR$1340=AV9,(($AP$6:$AP$1340)),0))/$AU$12} -> 0.22268557 | AX9: {=SUM(IF($AR$6:$AR$1340=AV9,($AM$6:$AM$1340),0))/SUM(IF($AR$6:$AR$1340=AV9,1,0))} -> 4439.5 | AY9: {=SUM(IF($AR$6:$AR$1340=AV9,($AO$6:$AO$1340),0))/SUM(IF($AR$6:$AR$1340=AV9,1,0))} -> 401 | BA9: 46025 | BB9: Shopping for Emi bday | BC9: 4 | BD9: 6838 | BE9: 7666 | BF9: 514 | BG9: 4 | BH9: 0.60902778 | BI9: Prime hours | BK9: Avg Max Viewers | BL9: =AVERAGE(BE6:BE1048576) -> 11344.077 | BM9: Great times | BN9: {=SUM(IF($BI$6:$BI$1340=BM9,(($BG$6:$BG$1340)),0))/$BL$12} -> 0.067615658 | BO9: {=SUM(IF($BI$6:$BI$1340=BM9,($BD$6:$BD$1340),0))/SUM(IF($BI$6:$BI$1340=BM9,1,0))} -> 12243 | BP9: {=SUM(IF($BI$6:$BI$1340=BM9,($BF$6:$BF$1340),0))/SUM(IF($BI$6:$BI$1340=BM9,1,0))} -> 1245 | BR9: 45983 | BS9: Doug Doug + Desktop | BT9: 5 | BU9: 3519 | BV9: 4758 | BW9: 733 | BX9: 13.5 | BY9: 0.82361111 | BZ9: Good times | CB9: Avg Max Viewers | CC9: =AVERAGE(BV6:BV1048576) -> 7524.963 | CD9: Great times | CE9: {=SUM(IF($BZ$6:$BZ$1340=CD9,(($BX$6:$BX$1340)),0))/$CC$12} -> 0.27307399 | CF9: {=SUM(IF($BZ$6:$BZ$1340=CD9,($BU$6:$BU$1340),0))/SUM(IF($BZ$6:$BZ$1340=CD9,1,0))} -> 4371.1429 | CG9: {=SUM(IF($BZ$6:$BZ$1340=CD9,($BW$6:$BW$1340),0))/SUM(IF($BZ$6:$BZ$1340=CD9,1,0))} -> 493.14286 | CI9: 46007 | CJ9: Painting w Ethero sob | CK9: 6 | CL9: 5016 | CM9: 6480 | CN9: 396 | CO9: 7.5 | CP9: 0.92152778 | CQ9: GG EST mfs | CS9: Avg Max Viewers | CT9: =AVERAGE(CM6:CM1048576) -> 7996.8 | CU9: Great times | CV9: {=SUM(IF($CQ$6:$CQ$1340=CU9,(($CO$6:$CO$1340)),0))/$CT$12} -> 0 | CW9: {=SUM(IF($CQ$6:$CQ$1340=CU9,($CL$6:$CL$1340),0))/SUM(IF($CQ$6:$CQ$1340=CU9,1,0))} -> #DIV/0! | CX9: {=SUM(IF($CQ$6:$CQ$1340=CU9,($CN$6:$CN$1340),0))/SUM(IF($CQ$6:$CQ$1340=CU9,1,0))} -> #DIV/0! | CZ9: 46066 | DA9: Ludwig basketball tourney | DB9: 7 | DC9: 3671 | DD9: 5775 | DE9: 351 | DF9: 13.3 | DG9: 0.51875 | DH9: Great times | DJ9: Avg Max Viewers | DK9: =AVERAGE(DD6:DD1048576) -> 7627.0714 | DL9: Great times | DM9: {=SUM(IF($DH$6:$DH$1340=DL9,(($DF$6:$DF$1340)),0))/$DK$12} -> 0.26274165 | DN9: {=SUM(IF($DH$6:$DH$1340=DL9,($DC$6:$DC$1340),0))/SUM(IF($DH$6:$DH$1340=DL9,1,0))} -> 5450 | DO9: {=SUM(IF($DH$6:$DH$1340=DL9,($DE$6:$DE$1340),0))/SUM(IF($DH$6:$DH$1340=DL9,1,0))} -> 569 | DQ9: 46107 | DR9: WE IN MIAMI, TURNING UP… | DS9: 8 | DT9: 4098 | DU9: 8544 | DV9: 231 | DW9: 7.2 | DX9: 0.64097222 | DY9: Prime hours | EA9: Avg Max Viewers | EB9: =AVERAGE(DU6:DU1048576) -> 7121 | EC9: Great times | ED9: {=SUM(IF($DY$6:$DY$1340=EC9,(($DW$6:$DW$1340)),0))/$EB$12} -> 0 | EE9: {=SUM(IF($DY$6:$DY$1340=EC9,($DT$6:$DT$1340),0))/SUM(IF($DY$6:$DY$1340=EC9,1,0))} -> #DIV/0! | EF9: {=SUM(IF($DY$6:$DY$1340=EC9,($DV$6:$DV$1340),0))/SUM(IF($DY$6:$DY$1340=EC9,1,0))} -> #DIV/0!
B10: 45997 | C10: Streamer awards aftermath | D10: 1 | E10: 9774 | F10: 15325 | G10: 802 | H10: 3.7 | I10: 0.95833333 | J10: GG EST mfs | K10: =E10 -> 9774 | L10: Total Streams | M10: =COUNT(D6:D1048576) -> 16 | N10: Good times | O10: {=SUM(IF($J$6:$J$1340=N10,(($H$6:$H$1340)),0))/$M$12} -> 0.46784566 | P10: {=SUM(IF($J$6:$J$1340=N10,($E$6:$E$1340),0))/SUM(IF($J$6:$J$1340=N10,1,0))} -> 3978.2857 | Q10: {=SUM(IF($J$6:$J$1340=N10,($G$6:$G$1340),0))/SUM(IF($J$6:$J$1340=N10,1,0))} -> 299.42857 | S10: 45990 | T10: USC Tailgate | U10: 2 | V10: 3876 | W10: 5282 | X10: 513 | Y10: 13.2 | Z10: 0.59305556 | AA10: Prime hours | AC10: Total Streams | AD10: =COUNT(U6:U1048576) -> 34 | AE10: Good times | AF10: {=SUM(IF($AA$6:$AA$1340=AE10,(($Y$6:$Y$1340)),0))/$AD$12} -> 0.15564087 | AG10: {=SUM(IF($AA$6:$AA$1340=AE10,($V$6:$V$1340),0))/SUM(IF($AA$6:$AA$1340=AE10,1,0))} -> 4906.3333 | AH10: {=SUM(IF($AA$6:$AA$1340=AE10,($X$6:$X$1340),0))/SUM(IF($AA$6:$AA$1340=AE10,1,0))} -> 486.33333 | AJ10: 46002 | AK10: OSCS Lake Tahoe snowboarding | AL10: 3 | AM10: 3557 | AN10: 4763 | AO10: 480 | AP10: 11.8 | AQ10: 0.62847222 | AR10: Prime hours | AT10: Total Streams | AU10: =COUNT(AL6:AL1048576) -> 14 | AV10: Good times | AW10: {=SUM(IF($AR$6:$AR$1340=AV10,(($AP$6:$AP$1340)),0))/$AU$12} -> 0.14178482 | AX10: {=SUM(IF($AR$6:$AR$1340=AV10,($AM$6:$AM$1340),0))/SUM(IF($AR$6:$AR$1340=AV10,1,0))} -> 4402 | AY10: {=SUM(IF($AR$6:$AR$1340=AV10,($AO$6:$AO$1340),0))/SUM(IF($AR$6:$AR$1340=AV10,1,0))} -> 273.66667 | BA10: 46047 | BB10: Motorcyle test + morebarky | BC10: 4 | BD10: 10685 | BE10: 14418 | BF10: 1280 | BG10: 11.4 | BH10: 0.44513889 | BI10: Early asf | BK10: Total Streams | BL10: =COUNT(BC6:BC1048576) -> 13 | BM10: Good times | BN10: {=SUM(IF($BI$6:$BI$1340=BM10,(($BG$6:$BG$1340)),0))/$BL$12} -> 0.48843416 | BO10: {=SUM(IF($BI$6:$BI$1340=BM10,($BD$6:$BD$1340),0))/SUM(IF($BI$6:$BI$1340=BM10,1,0))} -> 8204.8 | BP10: {=SUM(IF($BI$6:$BI$1340=BM10,($BF$6:$BF$1340),0))/SUM(IF($BI$6:$BI$1340=BM10,1,0))} -> 1204.2 | BR10: 45984 | BS10: China mukbang | BT10: 5 | BU10: 3146 | BV10: 4094 | BW10: 371 | BX10: 7.9 | BY10: 0.78541667 | BZ10: Good times | CB10: Total Streams | CC10: =COUNT(BT6:BT1048576) -> 27 | CD10: Good times | CE10: {=SUM(IF($BZ$6:$BZ$1340=CD10,(($BX$6:$BX$1340)),0))/$CC$12} -> 0.36384439 | CF10: {=SUM(IF($BZ$6:$BZ$1340=CD10,($BU$6:$BU$1340),0))/SUM(IF($BZ$6:$BZ$1340=CD10,1,0))} -> 5550.6364 | CG10: {=SUM(IF($BZ$6:$BZ$1340=CD10,($BW$6:$BW$1340),0))/SUM(IF($BZ$6:$BZ$1340=CD10,1,0))} -> 473.63636 | CI10: 46102 | CJ10: YDF last dance | CK10: 6 | CL10: 7742 | CM10: 11278 | CN10: 448 | CO10: 8.6 | CP10: 0.84027778 | CQ10: Late-night | CS10: Total Streams | CT10: =COUNT(CK6:CK1048576) -> 5 | CU10: Good times | CV10: {=SUM(IF($CQ$6:$CQ$1340=CU10,(($CO$6:$CO$1340)),0))/$CT$12} -> 0.34505495 | CW10: {=SUM(IF($CQ$6:$CQ$1340=CU10,($CL$6:$CL$1340),0))/SUM(IF($CQ$6:$CQ$1340=CU10,1,0))} -> 5601 | CX10: {=SUM(IF($CQ$6:$CQ$1340=CU10,($CN$6:$CN$1340),0))/SUM(IF($CQ$6:$CQ$1340=CU10,1,0))} -> 641.5 | CZ10: 46068 | DA10: Jynxzi RL tourney | DB10: 7 | DC10: 4781 | DD10: 6290 | DE10: 683 | DF10: 8.5 | DG10: 0.62916667 | DH10: Prime hours | DJ10: Total Streams | DK10: =COUNT(DB6:DB1048576) -> 14 | DL10: Good times | DM10: {=SUM(IF($DH$6:$DH$1340=DL10,(($DF$6:$DF$1340)),0))/$DK$12} -> 0.34885764 | DN10: {=SUM(IF($DH$6:$DH$1340=DL10,($DC$6:$DC$1340),0))/SUM(IF($DH$6:$DH$1340=DL10,1,0))} -> 5296.4 | DO10: {=SUM(IF($DH$6:$DH$1340=DL10,($DE$6:$DE$1340),0))/SUM(IF($DH$6:$DH$1340=DL10,1,0))} -> 320 | DQ10: 46109 | DR10: OSCS Cruise | DS10: 8 | DT10: 3887 | DU10: 6150 | DV10: 236 | DW10: 9.3 | DX10: 0.60138889 | DY10: Prime hours | EA10: Total Streams | EB10: =COUNT(DS6:DS1048576) -> 5 | EC10: Good times | ED10: {=SUM(IF($DY$6:$DY$1340=EC10,(($DW$6:$DW$1340)),0))/$EB$12} -> 0 | EE10: {=SUM(IF($DY$6:$DY$1340=EC10,($DT$6:$DT$1340),0))/SUM(IF($DY$6:$DY$1340=EC10,1,0))} -> #DIV/0! | EF10: {=SUM(IF($DY$6:$DY$1340=EC10,($DV$6:$DV$1340),0))/SUM(IF($DY$6:$DY$1340=EC10,1,0))} -> #DIV/0!
B11: 46009 | C11: Dr Tara + desktop | D11: 1 | E11: 5665 | F11: 10676 | G11: 244 | H11: 5.7 | I11: 0.78541667 | J11: Good times | K11: =E11 -> 5665 | L11: Total Followers Gained | M11: =COUNT(D6:D17) -> 12 | N11: Late-night | O11: {=SUM(IF($J$6:$J$1340=N11,(($H$6:$H$1340)),0))/$M$12} -> 0.081189711 | P11: {=SUM(IF($J$6:$J$1340=N11,($E$6:$E$1340),0))/SUM(IF($J$6:$J$1340=N11,1,0))} -> 3496 | Q11: {=SUM(IF($J$6:$J$1340=N11,($G$6:$G$1340),0))/SUM(IF($J$6:$J$1340=N11,1,0))} -> 521 | S11: 45993 | T11: Lost in OC | U11: 2 | V11: 3541 | W11: 4288 | X11: 320 | Y11: 5.9 | Z11: 0.65902778 | AA11: Prime hours | AC11: Total Followers Gained | AD11: =SUM(X6:X1048576) -> 21495 | AE11: Late-night | AF11: {=SUM(IF($AA$6:$AA$1340=AE11,(($Y$6:$Y$1340)),0))/$AD$12} -> 0.037802717 | AG11: {=SUM(IF($AA$6:$AA$1340=AE11,($V$6:$V$1340),0))/SUM(IF($AA$6:$AA$1340=AE11,1,0))} -> 5374 | AH11: {=SUM(IF($AA$6:$AA$1340=AE11,($X$6:$X$1340),0))/SUM(IF($AA$6:$AA$1340=AE11,1,0))} -> 432.5 | AJ11: 46004 | AK11: 6 flags + bunii concert | AL11: 3 | AM11: 4752 | AN11: 6973 | AO11: 540 | AP11: 10.8 | AQ11: 0.59375 | AR11: Prime hours | AT11: Total Followers Gained | AU11: =SUM(AO6:AO1048576) -> 5988 | AV11: Late-night | AW11: {=SUM(IF($AR$6:$AR$1340=AV11,(($AP$6:$AP$1340)),0))/$AU$12} -> 0.18181818 | AX11: {=SUM(IF($AR$6:$AR$1340=AV11,($AM$6:$AM$1340),0))/SUM(IF($AR$6:$AR$1340=AV11,1,0))} -> 6898.3333 | AY11: {=SUM(IF($AR$6:$AR$1340=AV11,($AO$6:$AO$1340),0))/SUM(IF($AR$6:$AR$1340=AV11,1,0))} -> 659.33333 | BA11: 46057 | BB11: Island survival w Bonnie | BC11: 4 | BD11: 10511 | BE11: 18238 | BF11: 3831 | BG11: 21.9 | BH11: 0.76875 | BI11: Good times | BK11: Total Followers Gained | BL11: =SUM(BF6:BF1048576) -> 11856 | BM11: Late-night | BN11: {=SUM(IF($BI$6:$BI$1340=BM11,(($BG$6:$BG$1340)),0))/$BL$12} -> 0.1316726 | BO11: {=SUM(IF($BI$6:$BI$1340=BM11,($BD$6:$BD$1340),0))/SUM(IF($BI$6:$BI$1340=BM11,1,0))} -> 7726 | BP11: {=SUM(IF($BI$6:$BI$1340=BM11,($BF$6:$BF$1340),0))/SUM(IF($BI$6:$BI$1340=BM11,1,0))} -> 604 | BR11: 45988 | BS11: OSCS Thanksgiving | BT11: 5 | BU11: 9347 | BV11: 13034 | BW11: 592 | BX11: 5.3 | BY11: 0.76319444 | BZ11: Good times | CB11: Total Followers Gained | CC11: =SUM(BW6:BW1048576) -> 12902 | CD11: Late-night | CE11: {=SUM(IF($BZ$6:$BZ$1340=CD11,(($BX$6:$BX$1340)),0))/$CC$12} -> 0.038520214 | CF11: {=SUM(IF($BZ$6:$BZ$1340=CD11,($BU$6:$BU$1340),0))/SUM(IF($BZ$6:$BZ$1340=CD11,1,0))} -> 6045 | CG11: {=SUM(IF($BZ$6:$BZ$1340=CD11,($BW$6:$BW$1340),0))/SUM(IF($BZ$6:$BZ$1340=CD11,1,0))} -> 295 | CS11: Total Followers Gained | CT11: =SUM(CN6:CN1048576) -> 3406 | CU11: Late-night | CV11: {=SUM(IF($CQ$6:$CQ$1340=CU11,(($CO$6:$CO$1340)),0))/$CT$12} -> 0.18901099 | CW11: {=SUM(IF($CQ$6:$CQ$1340=CU11,($CL$6:$CL$1340),0))/SUM(IF($CQ$6:$CQ$1340=CU11,1,0))} -> 7742 | CX11: {=SUM(IF($CQ$6:$CQ$1340=CU11,($CN$6:$CN$1340),0))/SUM(IF($CQ$6:$CQ$1340=CU11,1,0))} -> 448 | CZ11: 46074 | DA11: Yugi's event | DB11: 7 | DC11: 5182 | DD11: 6256 | DE11: 374 | DF11: 9.9 | DG11: 0.76597222 | DH11: Good times | DJ11: Total Followers Gained | DK11: =SUM(DE6:DE1048576) -> 5844 | DL11: Late-night | DM11: {=SUM(IF($DH$6:$DH$1340=DL11,(($DF$6:$DF$1340)),0))/$DK$12} -> 0 | DN11: {=SUM(IF($DH$6:$DH$1340=DL11,($DC$6:$DC$1340),0))/SUM(IF($DH$6:$DH$1340=DL11,1,0))} -> #DIV/0! | DO11: {=SUM(IF($DH$6:$DH$1340=DL11,($DE$6:$DE$1340),0))/SUM(IF($DH$6:$DH$1340=DL11,1,0))} -> #DIV/0! | EA11: Total Followers Gained | EB11: =SUM(DV6:DV1048576) -> 2384 | EC11: Late-night | ED11: {=SUM(IF($DY$6:$DY$1340=EC11,(($DW$6:$DW$1340)),0))/$EB$12} -> 0.34870317 | EE11: {=SUM(IF($DY$6:$DY$1340=EC11,($DT$6:$DT$1340),0))/SUM(IF($DY$6:$DY$1340=EC11,1,0))} -> 5245.5 | EF11: {=SUM(IF($DY$6:$DY$1340=EC11,($DV$6:$DV$1340),0))/SUM(IF($DY$6:$DY$1340=EC11,1,0))} -> 644.5
B12: 46017 | C12: Desktop debrief | D12: 1 | E12: 10220 | F12: 19088 | G12: 1451 | H12: 10.1 | I12: 0.66388889 | J12: Prime hours | K12: =E12 -> 10220 | L12: Total Hours Streamed | M12: =SUM(H6:H1048576) -> 124.4 | N12: Early asf | O12: {=SUM(IF($J$6:$J$1340=N12,(($H$6:$H$1340)),0))/$M$12} -> 0 | P12: {=SUM(IF($J$6:$J$1340=N12,($E$6:$E$1340),0))/SUM(IF($J$6:$J$1340=N12,1,0))} -> #DIV/0! | Q12: {=SUM(IF($J$6:$J$1340=N12,($G$6:$G$1340),0))/SUM(IF($J$6:$J$1340=N12,1,0))} -> #DIV/0! | S12: 45998 | T12: ZAMFAM Christmas | U12: 2 | V12: 6260 | W12: 14074 | X12: 923 | Y12: 8.3 | Z12: 0.80416667 | AA12: Good times | AC12: Total Hours Streamed | AD12: =SUM(Y6:Y1048576) -> 338.6 | AE12: Early asf | AF12: {=SUM(IF($AA$6:$AA$1340=AE12,(($Y$6:$Y$1340)),0))/$AD$12} -> 0 | AG12: {=SUM(IF($AA$6:$AA$1340=AE12,($V$6:$V$1340),0))/SUM(IF($AA$6:$AA$1340=AE12,1,0))} -> #DIV/0! | AH12: {=SUM(IF($AA$6:$AA$1340=AE12,($X$6:$X$1340),0))/SUM(IF($AA$6:$AA$1340=AE12,1,0))} -> #DIV/0! | AJ12: 46030 | AK12: "Climbing mt baldy" | AL12: 3 | AM12: 2565 | AN12: 2777 | AO12: 100 | AP12: 2 | AQ12: 0.59166667 | AR12: Prime hours | AT12: Total Hours Streamed | AU12: =SUM(AP6:AP1048576) -> 119.9 | AV12: Early asf | AW12: {=SUM(IF($AR$6:$AR$1340=AV12,(($AP$6:$AP$1340)),0))/$AU$12} -> 0 | AX12: {=SUM(IF($AR$6:$AR$1340=AV12,($AM$6:$AM$1340),0))/SUM(IF($AR$6:$AR$1340=AV12,1,0))} -> #DIV/0! | AY12: {=SUM(IF($AR$6:$AR$1340=AV12,($AO$6:$AO$1340),0))/SUM(IF($AR$6:$AR$1340=AV12,1,0))} -> #DIV/0! | BA12: 46059 | BB12: Thailand day 1 w kiko | BC12: 4 | BD12: 6815 | BE12: 8260 | BF12: 638 | BG12: 8.9 | BH12: 0.88194444 | BI12: Late-night | BK12: Total Hours Streamed | BL12: =SUM(BG6:BG1048576) -> 112.4 | BM12: Early asf | BN12: {=SUM(IF($BI$6:$BI$1340=BM12,(($BG$6:$BG$1340)),0))/$BL$12} -> 0.10142349 | BO12: {=SUM(IF($BI$6:$BI$1340=BM12,($BD$6:$BD$1340),0))/SUM(IF($BI$6:$BI$1340=BM12,1,0))} -> 10685 | BP12: {=SUM(IF($BI$6:$BI$1340=BM12,($BF$6:$BF$1340),0))/SUM(IF($BI$6:$BI$1340=BM12,1,0))} -> 1280 | BR12: 45996 | BS12: Streamer awards shopping | BT12: 5 | BU12: 3291 | BV12: 3858 | BW12: 192 | BX12: 6.6 | BY12: 0.63680556 | BZ12: Prime hours | CB12: Total Hours Streamed | CC12: =SUM(BX6:BX1048576) -> 262.2 | CD12: Early asf | CE12: {=SUM(IF($BZ$6:$BZ$1340=CD12,(($BX$6:$BX$1340)),0))/$CC$12} -> 0 | CF12: {=SUM(IF($BZ$6:$BZ$1340=CD12,($BU$6:$BU$1340),0))/SUM(IF($BZ$6:$BZ$1340=CD12,1,0))} -> #DIV/0! | CG12: {=SUM(IF($BZ$6:$BZ$1340=CD12,($BW$6:$BW$1340),0))/SUM(IF($BZ$6:$BZ$1340=CD12,1,0))} -> #DIV/0! | CS12: Total Hours Streamed | CT12: =SUM(CO6:CO1048576) -> 45.5 | CU12: Early asf | CV12: {=SUM(IF($CQ$6:$CQ$1340=CU12,(($CO$6:$CO$1340)),0))/$CT$12} -> 0 | CW12: {=SUM(IF($CQ$6:$CQ$1340=CU12,($CL$6:$CL$1340),0))/SUM(IF($CQ$6:$CQ$1340=CU12,1,0))} -> #DIV/0! | CX12: {=SUM(IF($CQ$6:$CQ$1340=CU12,($CN$6:$CN$1340),0))/SUM(IF($CQ$6:$CQ$1340=CU12,1,0))} -> #DIV/0! | CZ12: 46075 | DA12: Yugi's event | DB12: 7 | DC12: 3799 | DD12: 4757 | DE12: 247 | DF12: 11.2 | DG12: 0.72222222 | DH12: Good times | DJ12: Total Hours Streamed | DK12: =SUM(DF6:DF1048576) -> 113.8 | DL12: Early asf | DM12: {=SUM(IF($DH$6:$DH$1340=DL12,(($DF$6:$DF$1340)),0))/$DK$12} -> 0 | DN12: {=SUM(IF($DH$6:$DH$1340=DL12,($DC$6:$DC$1340),0))/SUM(IF($DH$6:$DH$1340=DL12,1,0))} -> #DIV/0! | DO12: {=SUM(IF($DH$6:$DH$1340=DL12,($DE$6:$DE$1340),0))/SUM(IF($DH$6:$DH$1340=DL12,1,0))} -> #DIV/0! | EA12: Total Hours Streamed | EB12: =SUM(DW6:DW1048576) -> 34.7 | EC12: Early asf | ED12: {=SUM(IF($DY$6:$DY$1340=EC12,(($DW$6:$DW$1340)),0))/$EB$12} -> 0 | EE12: {=SUM(IF($DY$6:$DY$1340=EC12,($DT$6:$DT$1340),0))/SUM(IF($DY$6:$DY$1340=EC12,1,0))} -> #DIV/0! | EF12: {=SUM(IF($DY$6:$DY$1340=EC12,($DV$6:$DV$1340),0))/SUM(IF($DY$6:$DY$1340=EC12,1,0))} -> #DIV/0!
B13: 46023 | C13: Debriefs | D13: 1 | E13: 4008 | F13: 5374 | G13: 227 | H13: 5.1 | I13: 0.95069444 | J13: GG EST mfs | K13: =E13 -> 4008 | N13: GG EST Mfs | O13: {=SUM(IF($J$6:$J$1340=N13,(($H$6:$H$1340)),0))/$M$12} -> 0.1221865 | P13: {=SUM(IF($J$6:$J$1340=N13,($E$6:$E$1340),0))/SUM(IF($J$6:$J$1340=N13,1,0))} -> 6388.6667 | Q13: {=SUM(IF($J$6:$J$1340=N13,($G$6:$G$1340),0))/SUM(IF($J$6:$J$1340=N13,1,0))} -> 465.33333 | S13: 46011 | T13: Quqco austin | U13: 2 | V13: 4906 | W13: 6021 | X13: 241 | Y13: 5 | Z13: 0.78194444 | AA13: Good times | AE13: GG EST Mfs | AF13: {=SUM(IF($AA$6:$AA$1340=AE13,(($Y$6:$Y$1340)),0))/$AD$12} -> 0 | AG13: {=SUM(IF($AA$6:$AA$1340=AE13,($V$6:$V$1340),0))/SUM(IF($AA$6:$AA$1340=AE13,1,0))} -> #DIV/0! | AH13: {=SUM(IF($AA$6:$AA$1340=AE13,($X$6:$X$1340),0))/SUM(IF($AA$6:$AA$1340=AE13,1,0))} -> #DIV/0! | AJ13: 46053 | AK13: NMS boxing aftermath | AL13: 3 | AM13: 11554 | AN13: 21997 | AO13: 828 | AP13: 6.7 | AQ13: 0.86319444 | AR13: Late-night | AV13: GG EST Mfs | AW13: {=SUM(IF($AR$6:$AR$1340=AV13,(($AP$6:$AP$1340)),0))/$AU$12} -> 0 | AX13: {=SUM(IF($AR$6:$AR$1340=AV13,($AM$6:$AM$1340),0))/SUM(IF($AR$6:$AR$1340=AV13,1,0))} -> #DIV/0! | AY13: {=SUM(IF($AR$6:$AR$1340=AV13,($AO$6:$AO$1340),0))/SUM(IF($AR$6:$AR$1340=AV13,1,0))} -> #DIV/0! | BA13: 46061 | BB13: Thailand day 2 | BC13: 4 | BD13: 5102 | BE13: 7057 | BF13: 217 | BG13: 4 | BH13: 0.11458333 | BI13: KeYS | BM13: GG EST Mfs | BN13: {=SUM(IF($BI$6:$BI$1340=BM13,(($BG$6:$BG$1340)),0))/$BL$12} -> 0 | BO13: {=SUM(IF($BI$6:$BI$1340=BM13,($BD$6:$BD$1340),0))/SUM(IF($BI$6:$BI$1340=BM13,1,0))} -> #DIV/0! | BP13: {=SUM(IF($BI$6:$BI$1340=BM13,($BF$6:$BF$1340),0))/SUM(IF($BI$6:$BI$1340=BM13,1,0))} -> #DIV/0! | BR13: 46005 | BS13: Finding MICA | BT13: 5 | BU13: 4178 | BV13: 5449 | BW13: 688 | BX13: 8.8 | BY13: 0.80069444 | BZ13: Good times | CD13: GG EST Mfs | CE13: {=SUM(IF($BZ$6:$BZ$1340=CD13,(($BX$6:$BX$1340)),0))/$CC$12} -> 0 | CF13: {=SUM(IF($BZ$6:$BZ$1340=CD13,($BU$6:$BU$1340),0))/SUM(IF($BZ$6:$BZ$1340=CD13,1,0))} -> #DIV/0! | CG13: {=SUM(IF($BZ$6:$BZ$1340=CD13,($BW$6:$BW$1340),0))/SUM(IF($BZ$6:$BZ$1340=CD13,1,0))} -> #DIV/0! | CU13: GG EST Mfs | CV13: {=SUM(IF($CQ$6:$CQ$1340=CU13,(($CO$6:$CO$1340)),0))/$CT$12} -> 0.16483516 | CW13: {=SUM(IF($CQ$6:$CQ$1340=CU13,($CL$6:$CL$1340),0))/SUM(IF($CQ$6:$CQ$1340=CU13,1,0))} -> 5016 | CX13: {=SUM(IF($CQ$6:$CQ$1340=CU13,($CN$6:$CN$1340),0))/SUM(IF($CQ$6:$CQ$1340=CU13,1,0))} -> 396 | CZ13: 46078 | DA13: Pop the balloon for Guapo | DB13: 7 | DC13: 8032 | DD13: 9676 | DE13: 98 | DF13: 1.9 | DG13: 0.65138889 | DH13: Prime hours | DL13: GG EST Mfs | DM13: {=SUM(IF($DH$6:$DH$1340=DL13,(($DF$6:$DF$1340)),0))/$DK$12} -> 0 | DN13: {=SUM(IF($DH$6:$DH$1340=DL13,($DC$6:$DC$1340),0))/SUM(IF($DH$6:$DH$1340=DL13,1,0))} -> #DIV/0! | DO13: {=SUM(IF($DH$6:$DH$1340=DL13,($DE$6:$DE$1340),0))/SUM(IF($DH$6:$DH$1340=DL13,1,0))} -> #DIV/0! | EC13: GG EST Mfs | ED13: {=SUM(IF($DY$6:$DY$1340=EC13,(($DW$6:$DW$1340)),0))/$EB$12} -> 0.17579251 | EE13: {=SUM(IF($DY$6:$DY$1340=EC13,($DT$6:$DT$1340),0))/SUM(IF($DY$6:$DY$1340=EC13,1,0))} -> 5671 | EF13: {=SUM(IF($DY$6:$DY$1340=EC13,($DV$6:$DV$1340),0))/SUM(IF($DY$6:$DY$1340=EC13,1,0))} -> 628
B14: 46033 | C14: ARK | D14: 1 | E14: 5384 | F14: 7099 | G14: 367 | H14: 6.4 | I14: 0.94513889 | J14: GG EST mfs | K14: =E14 -> 5384 | N14: Lol | O14: {=SUM(IF($J$6:$J$1340=N14,(($H$6:$H$1340)),0))/$M$12} -> 0 | P14: {=SUM(IF($J$6:$J$1340=N14,($E$6:$E$1340),0))/SUM(IF($J$6:$J$1340=N14,1,0))} -> #DIV/0! | Q14: {=SUM(IF($J$6:$J$1340=N14,($G$6:$G$1340),0))/SUM(IF($J$6:$J$1340=N14,1,0))} -> #DIV/0! | S14: 46013 | T14: ExtraEmily impractical jokers | U14: 2 | V14: 5472 | W14: 7261 | X14: 695 | Y14: 7.1 | Z14: 0.58333333 | AA14: Prime hours | AE14: Lol | AF14: {=SUM(IF($AA$6:$AA$1340=AE14,(($Y$6:$Y$1340)),0))/$AD$12} -> 0 | AG14: {=SUM(IF($AA$6:$AA$1340=AE14,($V$6:$V$1340),0))/SUM(IF($AA$6:$AA$1340=AE14,1,0))} -> #DIV/0! | AH14: {=SUM(IF($AA$6:$AA$1340=AE14,($X$6:$X$1340),0))/SUM(IF($AA$6:$AA$1340=AE14,1,0))} -> #DIV/0! | AJ14: 46114 | AK14: Lost in Austin w Zoil | AL14: 3 | AM14: 4962 | AN14: 7262 | AO14: 270 | AP14: 12.5 | AQ14: 0.57361111 | AR14: Great times | AV14: Lol | AW14: {=SUM(IF($AR$6:$AR$1340=AV14,(($AP$6:$AP$1340)),0))/$AU$12} -> 0 | AX14: {=SUM(IF($AR$6:$AR$1340=AV14,($AM$6:$AM$1340),0))/SUM(IF($AR$6:$AR$1340=AV14,1,0))} -> #DIV/0! | AY14: {=SUM(IF($AR$6:$AR$1340=AV14,($AO$6:$AO$1340),0))/SUM(IF($AR$6:$AR$1340=AV14,1,0))} -> #DIV/0! | BA14: 46061 | BB14: Thailand day 3 | BC14: 4 | BD14: 8637 | BE14: 10534 | BF14: 570 | BG14: 5.9 | BH14: 0.86805556 | BI14: Late-night | BM14: Lol | BN14: {=SUM(IF($BI$6:$BI$1340=BM14,(($BG$6:$BG$1340)),0))/$BL$12} -> 0.053380783 | BO14: {=SUM(IF($BI$6:$BI$1340=BM14,($BD$6:$BD$1340),0))/SUM(IF($BI$6:$BI$1340=BM14,1,0))} -> 6538 | BP14: {=SUM(IF($BI$6:$BI$1340=BM14,($BF$6:$BF$1340),0))/SUM(IF($BI$6:$BI$1340=BM14,1,0))} -> 564 | BR14: 46006 | BS14: Doug Doug, 6 flags | BT14: 5 | BU14: 3327 | BV14: 4846 | BW14: 218 | BX14: 4.3 | BY14: 0.50416667 | BZ14: Great times | CD14: Lol | CE14: {=SUM(IF($BZ$6:$BZ$1340=CD14,(($BX$6:$BX$1340)),0))/$CC$12} -> 0 | CF14: {=SUM(IF($BZ$6:$BZ$1340=CD14,($BU$6:$BU$1340),0))/SUM(IF($BZ$6:$BZ$1340=CD14,1,0))} -> #DIV/0! | CG14: {=SUM(IF($BZ$6:$BZ$1340=CD14,($BW$6:$BW$1340),0))/SUM(IF($BZ$6:$BZ$1340=CD14,1,0))} -> #DIV/0! | CU14: Lol | CV14: {=SUM(IF($CQ$6:$CQ$1340=CU14,(($CO$6:$CO$1340)),0))/$CT$12} -> 0 | CW14: {=SUM(IF($CQ$6:$CQ$1340=CU14,($CL$6:$CL$1340),0))/SUM(IF($CQ$6:$CQ$1340=CU14,1,0))} -> #DIV/0! | CX14: {=SUM(IF($CQ$6:$CQ$1340=CU14,($CN$6:$CN$1340),0))/SUM(IF($CQ$6:$CQ$1340=CU14,1,0))} -> #DIV/0! | CZ14: 46080 | DA14: Mr beast streamer vid (shhhh) | DB14: 7 | DC14: 2351 | DD14: 6110 | DE14: 150 | DF14: 1.5 | DG14: 0.31388889 | DH14: KeYS | DL14: Lol | DM14: {=SUM(IF($DH$6:$DH$1340=DL14,(($DF$6:$DF$1340)),0))/$DK$12} -> 0 | DN14: {=SUM(IF($DH$6:$DH$1340=DL14,($DC$6:$DC$1340),0))/SUM(IF($DH$6:$DH$1340=DL14,1,0))} -> #DIV/0! | DO14: {=SUM(IF($DH$6:$DH$1340=DL14,($DE$6:$DE$1340),0))/SUM(IF($DH$6:$DH$1340=DL14,1,0))} -> #DIV/0! | EC14: Lol | ED14: {=SUM(IF($DY$6:$DY$1340=EC14,(($DW$6:$DW$1340)),0))/$EB$12} -> 0 | EE14: {=SUM(IF($DY$6:$DY$1340=EC14,($DT$6:$DT$1340),0))/SUM(IF($DY$6:$DY$1340=EC14,1,0))} -> #DIV/0! | EF14: {=SUM(IF($DY$6:$DY$1340=EC14,($DV$6:$DV$1340),0))/SUM(IF($DY$6:$DY$1340=EC14,1,0))} -> #DIV/0!
B15: 46065 | C15: Debrief of thailand + "OSCS" day | D15: 1 | E15: 6091 | F15: 9276 | G15: 546 | H15: 12.6 | I15: 0.55277778 | J15: Great times | K15: =E15 -> 6091 | N15: KeYS | O15: {=SUM(IF($J$6:$J$1340=N15,(($H$6:$H$1340)),0))/$M$12} -> 0 | P15: {=SUM(IF($J$6:$J$1340=N15,($E$6:$E$1340),0))/SUM(IF($J$6:$J$1340=N15,1,0))} -> #DIV/0! | Q15: {=SUM(IF($J$6:$J$1340=N15,($G$6:$G$1340),0))/SUM(IF($J$6:$J$1340=N15,1,0))} -> #DIV/0! | S15: 46020 | T15: Snowboarding w Blau | U15: 2 | V15: 3313 | W15: 4107 | X15: 269 | Y15: 4.3 | Z15: 0.7 | AA15: Prime hours | AE15: KeYS | AF15: {=SUM(IF($AA$6:$AA$1340=AE15,(($Y$6:$Y$1340)),0))/$AD$12} -> 0 | AG15: {=SUM(IF($AA$6:$AA$1340=AE15,($V$6:$V$1340),0))/SUM(IF($AA$6:$AA$1340=AE15,1,0))} -> #DIV/0! | AH15: {=SUM(IF($AA$6:$AA$1340=AE15,($X$6:$X$1340),0))/SUM(IF($AA$6:$AA$1340=AE15,1,0))} -> #DIV/0! | AJ15: 46117 | AK15: Knutt's Easter, balesh, and forest | AL15: 3 | AM15: 7155 | AN15: 12070 | AO15: 557 | AP15: 10.2 | AQ15: 0.63194444 | AR15: Prime hours | AV15: KeYS | AW15: {=SUM(IF($AR$6:$AR$1340=AV15,(($AP$6:$AP$1340)),0))/$AU$12} -> 0 | AX15: {=SUM(IF($AR$6:$AR$1340=AV15,($AM$6:$AM$1340),0))/SUM(IF($AR$6:$AR$1340=AV15,1,0))} -> #DIV/0! | AY15: {=SUM(IF($AR$6:$AR$1340=AV15,($AO$6:$AO$1340),0))/SUM(IF($AR$6:$AR$1340=AV15,1,0))} -> #DIV/0! | BA15: 46063 | BB15: Thailand day 4 | BC15: 4 | BD15: 6538 | BE15: 9311 | BF15: 564 | BG15: 6 | BH15: 0.0034722222 | BI15: Lol | BM15: KeYS | BN15: {=SUM(IF($BI$6:$BI$1340=BM15,(($BG$6:$BG$1340)),0))/$BL$12} -> 0.035587189 | BO15: {=SUM(IF($BI$6:$BI$1340=BM15,($BD$6:$BD$1340),0))/SUM(IF($BI$6:$BI$1340=BM15,1,0))} -> 5102 | BP15: {=SUM(IF($BI$6:$BI$1340=BM15,($BF$6:$BF$1340),0))/SUM(IF($BI$6:$BI$1340=BM15,1,0))} -> 217 | BR15: 46021 | BS15: Desktop + bench | BT15: 5 | BU15: 5016 | BV15: 8267 | BW15: 881 | BX15: 12.4 | BY15: 0.69375 | BZ15: Prime hours | CD15: KeYS | CE15: {=SUM(IF($BZ$6:$BZ$1340=CD15,(($BX$6:$BX$1340)),0))/$CC$12} -> 0 | CF15: {=SUM(IF($BZ$6:$BZ$1340=CD15,($BU$6:$BU$1340),0))/SUM(IF($BZ$6:$BZ$1340=CD15,1,0))} -> #DIV/0! | CG15: {=SUM(IF($BZ$6:$BZ$1340=CD15,($BW$6:$BW$1340),0))/SUM(IF($BZ$6:$BZ$1340=CD15,1,0))} -> #DIV/0! | CU15: KeYS | CV15: {=SUM(IF($CQ$6:$CQ$1340=CU15,(($CO$6:$CO$1340)),0))/$CT$12} -> 0 | CW15: {=SUM(IF($CQ$6:$CQ$1340=CU15,($CL$6:$CL$1340),0))/SUM(IF($CQ$6:$CQ$1340=CU15,1,0))} -> #DIV/0! | CX15: {=SUM(IF($CQ$6:$CQ$1340=CU15,($CN$6:$CN$1340),0))/SUM(IF($CQ$6:$CQ$1340=CU15,1,0))} -> #DIV/0! | CZ15: 46096 | DA15: Jynxzi cs tourney | DB15: 7 | DC15: 3589 | DD15: 6488 | DE15: 821 | DF15: 12 | DG15: 0.58611111 | DH15: Prime hours | DL15: KeYS | DM15: {=SUM(IF($DH$6:$DH$1340=DL15,(($DF$6:$DF$1340)),0))/$DK$12} -> 0.013181019 | DN15: {=SUM(IF($DH$6:$DH$1340=DL15,($DC$6:$DC$1340),0))/SUM(IF($DH$6:$DH$1340=DL15,1,0))} -> 2351 | DO15: {=SUM(IF($DH$6:$DH$1340=DL15,($DE$6:$DE$1340),0))/SUM(IF($DH$6:$DH$1340=DL15,1,0))} -> 150 | EC15: KeYS | ED15: {=SUM(IF($DY$6:$DY$1340=EC15,(($DW$6:$DW$1340)),0))/$EB$12} -> 0 | EE15: {=SUM(IF($DY$6:$DY$1340=EC15,($DT$6:$DT$1340),0))/SUM(IF($DY$6:$DY$1340=EC15,1,0))} -> #DIV/0! | EF15: {=SUM(IF($DY$6:$DY$1340=EC15,($DV$6:$DV$1340),0))/SUM(IF($DY$6:$DY$1340=EC15,1,0))} -> #DIV/0!
B16: 46077 | C16: ARK | D16: 1 | E16: 2811 | F16: 3811 | G16: 163 | H16: 8 | I16: 0.82430556 | J16: Good times | K16: =E16 -> 2811 | S16: 46028 | T16: Mr beast show | U16: 2 | V16: 7780 | W16: 16710 | X16: 1143 | Y16: 10.3 | Z16: 0.69097222 | AA16: Prime hours | AJ16: 46128 | AK16: YDF first dance sob | AL16: 3 | AM16: 4800 | AN16: 6713 | AO16: 217 | AP16: 9.1 | AQ16: 0.81666667 | AR16: Good times | BA16: 46067 | BB16: Valentines day w Bonnie | BC16: 4 | BD16: 12614 | BE16: 16729 | BF16: 542 | BG16: 3.5 | BH16: 0.74652778 | BI16: Good times | BR16: 46022 | BS16: OSCS new years | BT16: 5 | BU16: 6045 | BV16: 9010 | BW16: 295 | BX16: 10.1 | BY16: 0.83333333 | BZ16: Late-night | CZ16: 46103 | DA16: OSCS soccer tourney | DB16: 7 | DC16: 6703 | DD16: 8156 | DE16: 249 | DF16: 4.4 | DG16: 0.72083333 | DH16: Good times
B17: 46088 | C17: Debrief of India | D17: 1 | E17: 4596 | F17: 7325 | G17: 339 | H17: 7.8 | I17: 0.80486111 | J17: Good times | K17: =E17 -> 4596 | S17: 46034 | T17: SIMS w yusuf | U17: 2 | V17: 3900 | W17: 6861 | X17: 635 | Y17: 12.4 | Z17: 0.63194444 | AA17: Prime hours | AJ17: 46136 | AK17: 100k geo guess + party for suburbs talk | AL17: 3 | AM17: 3917 | AN17: 6371 | AO17: 532 | AP17: 14.2 | AQ17: 0.57013889 | AR17: Great times | BA17: 46094 | BB17: Lost in LA w Bonnie | BC17: 4 | BD17: 6531 | BE17: 8181 | BF17: 460 | BG17: 10.1 | BH17: 0.71458333 | BI17: Good times | BR17: 46026 | BS17: Doug Doug OC fair | BT17: 5 | BU17: 4845 | BV17: 7142 | BW17: 501 | BX17: 8 | BY17: 0.83055556 | BZ17: Good times | CZ17: 46112 | DA17: Fanum $50K RL tourney | DB17: 7 | DC17: 4394 | DD17: 5872 | DE17: 99 | DF17: 3.7 | DG17: 0.72361111 | DH17: Good times
B18: 46129 | C18: ARK Day + Sidemen charity match | D18: 1 | E18: 4276 | F18: 8634 | G18: 619 | H18: 15.4 | I18: 0.77222222 | J18: Good times | S18: 46036 | T18: American ninja warrior w yonna | U18: 2 | V18: 4456 | W18: 5317 | X18: 492 | Y18: 4.5 | Z18: 0.55902778 | AA18: Great times | AJ18: 46139 | AK18: desktop + sneaking into girls night | AL18: 3 | AM18: 5088 | AN18: 7964 | AO18: 528 | AP18: 13.4 | AQ18: 0.66041667 | AR18: Prime hours | BA18: 46116 | BB18: Bro v Sis w Bonnie | BC18: 4 | BD18: 7450 | BE18: 9748 | BF18: 387 | BG18: 7.2 | BH18: 0.78472222 | BI18: Good times | BR18: 46027 | BS18: Doug Doug world record | BT18: 5 | BU18: 6665 | BV18: 21692 | BW18: 1141 | BX18: 11.5 | BY18: 0.64236111 | BZ18: Prime hours | CZ18: 46120 | DA18: Max's diss wars + balesh | DB18: 7 | DC18: 7203 | DD18: 9911 | DE18: 312 | DF18: 8.3 | DG18: 0.68333333 | DH18: Prime hours
B19: 46137 | C19: R6 tourney + arksmp (blind date sob) | D19: 1 | E19: 2794 | F19: 4724 | G19: 286 | H19: 11.6 | I19: 0.61736111 | J19: Prime hours | S19: 46037 | T19: Signing w Byrant Barnes + boxing | U19: 2 | V19: 4305 | W19: 9727 | X19: 554 | Y19: 11.1 | Z19: 0.58055556 | AA19: Great times | AJ19: 46143 | AK19: Lost in Toronto | AL19: 3 | AM19: 4201 | AN19: 6869 | AO19: 182 | AP19: 6.2 | AQ19: 0.60069444 | AR19: Prime hours | BR19: 46031 | BS19: OSCS game night | BT19: 5 | BU19: 4680 | BV19: 8300 | BW19: 1048 | BX19: 17.8 | BY19: 0.51736111 | BZ19: Great times | CZ19: 46125 | DA19: OSCS Austin house party | DB19: 7 | DC19: 7229 | DD19: 10018 | DE19: 787 | DF19: 16.6 | DG19: 0.46180556 | DH19: Great times
B20: 46140 | C20: VR PARTY | D20: 1 | E20: 4198 | F20: 5499 | G20: 100 | H20: 5 | I20: 0.80208333 | J20: Good times | S20: 46040 | T20: Truth or nasty w Hasan | U20: 2 | V20: 4797 | W20: 7394 | X20: 1386 | Y20: 10.1 | Z20: 0.575 | AA20: Great times | BR20: 46035 | BS20: OSCS soap box | BT20: 5 | BU20: 3682 | BV20: 5063 | BW20: 456 | BX20: 12.6 | BY20: 0.56736111 | BZ20: Great times
B21: 46144 | C21: Toronto debrief | D21: 1 | E21: 12436 | F21: 16928 | G21: 573 | H21: 2.7 | I21: 0.52361111 | J21: Great times | S21: 46042 | T21: OSCS Day w Silky | U21: 2 | V21: 4745 | W21: 7147 | X21: 417 | Y21: 9.4 | Z21: 0.76319444 | AA21: Good times | BR21: 46039 | BS21: Running a mile vs Santi | BT21: 5 | BU21: 6959 | BV21: 9048 | BW21: 460 | BX21: 8.5 | BY21: 0.73263889 | BZ21: Good times
S22: 46045 | T22: OSCS v suburb talks | U22: 2 | V22: 4079 | W22: 6171 | X22: 316 | Y22: 10.3 | Z22: 0.60347222 | AA22: Prime hours | BR22: 46071 | BS22: Debrief + sunny | BT22: 5 | BU22: 3963 | BV22: 5720 | BW22: 427 | BX22: 13.7 | BY22: 0.66319444 | BZ22: Prime hours
S23: 46049 | T23: Mukbang w Maru + Bigmon origin | U23: 2 | V23: 5423 | W23: 7410 | X23: 399 | Y23: 6.7 | Z23: 0.84791667 | AA23: Late-night | BR23: 46072 | BS23: ARK | BT23: 5 | BU23: 4487 | BV23: 7437 | BW23: 298 | BX23: 11.3 | BY23: 0.67638889 | BZ23: Prime hours
S24: 46051 | T24: Facebook mukbang w Sakura | U24: 2 | V24: 5689 | W24: 11032 | X24: 1323 | Y24: 15.1 | Z24: 0.56041667 | AA24: Great times | BR24: 46091 | BS24: Sex edu w Tara + soccer | BT24: 5 | BU24: 4192 | BV24: 6632 | BW24: 387 | BX24: 12.2 | BY24: 0.62708333 | BZ24: Prime hours
S25: 46052 | T25: Dumpster diving w Paige | U25: 2 | V25: 5325 | W25: 8524 | X25: 466 | Y25: 6.1 | Z25: 0.86041667 | AA25: Late-night | BR25: 46092 | BS25: Doug Doug knotts berry farm | BT25: 5 | BU25: 5112 | BV25: 6196 | BW25: 287 | BX25: 5 | BY25: 0.50347222 | BZ25: Great times
S26: 46053 | T26: NMS boxing pregame w ZUGOI | U26: 2 | V26: 11590 | W26: 15132 | X26: 645 | Y26: 4.3 | Z26: 0.55208333 | AA26: Great times | BR26: 46099 | BS26: YDF day 1 | BT26: 5 | BU26: 7256 | BV26: 11579 | BW26: 502 | BX26: 7.9 | BY26: 0.78402778 | BZ26: Good times
S27: 46054 | T27: OSCS day w Ray | U27: 2 | V27: 5914 | W27: 9309 | X27: 1221 | Y27: 10.1 | Z27: 0.61666667 | AA27: Prime hours | BR27: 46101 | BS27: YDF day 2 + futbol prac | BT27: 5 | BU27: 6485 | BV27: 8502 | BW27: 442 | BX27: 10.7 | BY27: 0.77083333 | BZ27: Good times
S28: 46076 | T28: Gross ones w yusuf | U28: 2 | V28: 4822 | W28: 0 | X28: 341 | Y28: 12.2 | Z28: 0.77222222 | AA28: Good times | BR28: 46105 | BS28: QT & ada canceled, so we got some bs | BT28: 5 | BU28: 5708 | BV28: 9557 | BW28: 380 | BX28: 14.8 | BY28: 0.58888889 | BZ28: Prime hours
S29: 46089 | T29: Jynxzi R6 tourney + barky + games | U29: 2 | V29: 4050 | W29: 10950 | X29: 1010 | Y29: 14.5 | Z29: 0.55833333 | AA29: Great times | BR29: 46113 | BS29: OSCS House reveal | BT29: 5 | BU29: 5395 | BV29: 6807 | BW29: 396 | BX29: 9.9 | BY29: 0.55486111 | BZ29: Great times
S30: 46090 | T30: Muay thai w Syanne + Ron + sunny hinge | U30: 2 | V30: 6183 | W30: 19591 | X30: 1031 | Y30: 13.1 | Z30: 0.525 | AA30: Great times | BR30: 46115 | BS30: OSCS balesh day | BT30: 5 | BU30: 3934 | BV30: 5268 | BW30: 278 | BX30: 12.1 | BY30: 0.47986111 | BZ30: Great times
S31: 46095 | T31: OSCS day w Ron + joe bro v bro | U31: 2 | V31: 4188 | W31: 6352 | X31: 586 | Y31: 12.3 | Z31: 0.48194444 | AA31: Great times | BR31: 46121 | BS31: OSCS podcast w wakewilder | BT31: 5 | BU31: 4938 | BV31: 6537 | BW31: 213 | BX31: 9.4 | BY31: 0.72152778 | BZ31: Good times
S32: 46100 | T32: OSCS day w Yonna & Ray + Sunny 20v1 | U32: 2 | V32: 6477 | W32: 9402 | X32: 1008 | Y32: 13.5 | Z32: 0.61458333 | AA32: Prime hours | BR32: 46131 | BS32: Desktop + Sunday league soccer | BT32: 5 | BU32: 4827 | BV32: 6128 | BW32: 184 | BX32: 6.2 | BY32: 0.81944444 | BZ32: Good times
S33: 46119 | T33: Doug Doug 1v1 w Katchi + balesh | U33: 2 | V33: 5597 | W33: 8984 | X33: 661 | Y33: 13.7 | Z33: 0.50972222 | AA33: Great times
S34: 46122 | T34: 2v2 w Yamfam v Lemon & Zugoi | U34: 2 | V34: 3540 | W34: 4681 | X34: 255 | Y34: 12.6 | Z34: 0.60833333 | AA34: Prime hours
S35: 46123 | T35: OSCS day w ExtraEmily | U35: 2 | V35: 5434 | W35: 7552 | X35: 442 | Y35: 13.6 | Z35: 0.53472222 | AA35: Great times
S36: 46127 | T36: Games and reacts w Yonna | U36: 2 | V36: 5408 | W36: 8813 | X36: 562 | Y36: 11 | Z36: 0.75277778 | AA36: Good times
S37: 46132 | T37: IRL LA Bingo w yusuf & max | U37: 2 | V37: 4353 | W37: 6604 | X37: 268 | Y37: 10.4 | Z37: 0.66527778 | AA37: Prime hours
S38: 46135 | T38: Impractical jokers w yusuf, 24, & guapo | U38: 2 | V38: 4659 | W38: 5499 | X38: 369 | Y38: 11.5 | Z38: 0.56666667 | AA38: Great times
S39: 46142 | T39: Arky + Yonna balesh | U39: 2 | V39: 4514 | W39: 6003 | X39: 325 | Y39: 7.4 | Z39: 0.57083333 | AA39: Great times

Sheet In-Depth Analysis
C5: Mean Results, Concurrent Viewership
C6: Column1 | D6: Prime hours | E6: Great times | F6: Good times | G6: Late-night | H6: Early asf | I6: GG EST Mfs | J6: Lol | K6: KeYS | L6: μ | M6: 𝜎
C7: Desktop + Gaming | D7: ='Concept(s) Analysis Breakdown'!P8 -> 6507 | E7: ='Concept(s) Analysis Breakdown'!P9 -> 7483 | F7: ='Concept(s) Analysis Breakdown'!P10 -> 3978.2857 | G7: ='Concept(s) Analysis Breakdown'!P11 -> 3496 | H7: =IFERROR('Concept(s) Analysis Breakdown'!P12,0) -> 0 | I7: =IFERROR('Concept(s) Analysis Breakdown'!P13,0) -> 6388.6667 | J7: =IFERROR('Concept(s) Analysis Breakdown'!P14,0) -> 0 | K7: =IFERROR('Concept(s) Analysis Breakdown'!P15,0) -> 0 | L7: {=AVERAGE(IF(D7:K7>0,D7:K7))} -> 5570.5905 | M7: {=_xlfn.STDEV.S(IF(D7:K7>0,D7:K7))} -> 1735.1356
C8: Collab | D8: ='Concept(s) Analysis Breakdown'!AG8 -> 4648.0833 | E8: ='Concept(s) Analysis Breakdown'!AG9 -> 5326.1429 | F8: ='Concept(s) Analysis Breakdown'!AG10 -> 4906.3333 | G8: ='Concept(s) Analysis Breakdown'!AG11 -> 5374 | H8: =IFERROR('Concept(s) Analysis Breakdown'!AG12,0) -> 0 | I8: =IFERROR('Concept(s) Analysis Breakdown'!AG13,0) -> 0 | J8: =IFERROR('Concept(s) Analysis Breakdown'!AG14,0) -> 0 | K8: =IFERROR('Concept(s) Analysis Breakdown'!AG15,0) -> 0 | L8: {=AVERAGE(IF(D8:K8>0,D8:K8))} -> 5063.6399 | M8: {=_xlfn.STDEV.S(IF(D8:K8>0,D8:K8))} -> 347.68943
C9: IRL | D9: ='Concept(s) Analysis Breakdown'!AX8 -> 4553 | E9: =IFERROR('Concept(s) Analysis Breakdown'!AX9,0) -> 4439.5 | F9: ='Concept(s) Analysis Breakdown'!AX10 -> 4402 | G9: ='Concept(s) Analysis Breakdown'!AX11 -> 6898.3333 | H9: =IFERROR('Concept(s) Analysis Breakdown'!AX12,0) -> 0 | I9: =IFERROR('Concept(s) Analysis Breakdown'!AX13,0) -> 0 | J9: =IFERROR('Concept(s) Analysis Breakdown'!AX14,0) -> 0 | K9: =IFERROR('Concept(s) Analysis Breakdown'!AX15,0) -> 0 | L9: {=AVERAGE(IF(D9:K9>0,D9:K9))} -> 5073.2083 | M9: {=_xlfn.STDEV.S(IF(D9:K9>0,D9:K9))} -> 1218.4423
C10: Barky | D10: ='Concept(s) Analysis Breakdown'!BO8 -> 7091.5 | E10: ='Concept(s) Analysis Breakdown'!BO9 -> 12243 | F10: ='Concept(s) Analysis Breakdown'!BO10 -> 8204.8 | G10: ='Concept(s) Analysis Breakdown'!BO11 -> 7726 | H10: ='Concept(s) Analysis Breakdown'!BO12 -> 10685 | I10: =IFERROR('Concept(s) Analysis Breakdown'!BO13,0) -> 0 | J10: ='Concept(s) Analysis Breakdown'!BO14 -> 6538 | K10: ='Concept(s) Analysis Breakdown'!BO15 -> 5102 | L10: {=AVERAGE(IF(D10:K10>0,D10:K10))} -> 8227.1857 | M10: {=_xlfn.STDEV.S(IF(D10:K10>0,D10:K10))} -> 2460.6645
C11: OSCS bs | D11: ='Concept(s) Analysis Breakdown'!CF8 -> 4467.75 | E11: ='Concept(s) Analysis Breakdown'!CF9 -> 4371.1429 | F11: ='Concept(s) Analysis Breakdown'!CF10 -> 5550.6364 | G11: ='Concept(s) Analysis Breakdown'!CF11 -> 6045 | H11: =IFERROR('Concept(s) Analysis Breakdown'!CF12,0) -> 0 | I11: =IFERROR('Concept(s) Analysis Breakdown'!CF13,0) -> 0 | J11: =IFERROR('Concept(s) Analysis Breakdown'!CF14,0) -> 0 | K11: =IFERROR('Concept(s) Analysis Breakdown'!CF15,0) -> 0 | L11: {=AVERAGE(IF(D11:K11>0,D11:K11))} -> 5108.6323 | M11: {=_xlfn.STDEV.S(IF(D11:K11>0,D11:K11))} -> 821.9434
C12: Rizz | D12: ='Concept(s) Analysis Breakdown'!CW8 -> 5596 | E12: =IFERROR('Concept(s) Analysis Breakdown'!CW9,0) -> 0 | F12: ='Concept(s) Analysis Breakdown'!CW10 -> 5601 | G12: ='Concept(s) Analysis Breakdown'!CW11 -> 7742 | H12: =IFERROR('Concept(s) Analysis Breakdown'!CW12,0) -> 0 | I12: ='Concept(s) Analysis Breakdown'!CW13 -> 5016 | J12: =IFERROR('Concept(s) Analysis Breakdown'!CW14,0) -> 0 | K12: =IFERROR('Concept(s) Analysis Breakdown'!CW15,0) -> 0 | L12: {=AVERAGE(IF(D12:K12>0,D12:K12))} -> 5988.75 | M12: {=_xlfn.STDEV.S(IF(D12:K12>0,D12:K12))} -> 1200.6569
C13: Events | D13: ='Concept(s) Analysis Breakdown'!DN8 -> 5539.1667 | E13: ='Concept(s) Analysis Breakdown'!DN9 -> 5450 | F13: ='Concept(s) Analysis Breakdown'!DN10 -> 5296.4 | G13: =IFERROR('Concept(s) Analysis Breakdown'!DN11,0) -> 0 | H13: =IFERROR('Concept(s) Analysis Breakdown'!DN12,0) -> 0 | I13: =IFERROR('Concept(s) Analysis Breakdown'!DN13,0) -> 0 | J13: =IFERROR('Concept(s) Analysis Breakdown'!DN14,0) -> 0 | K13: ='Concept(s) Analysis Breakdown'!DN15 -> 2351 | L13: {=AVERAGE(IF(D13:K13>0,D13:K13))} -> 4659.1417 | M13: {=_xlfn.STDEV.S(IF(D13:K13>0,D13:K13))} -> 1542.0243
C14: Travels | D14: =IFERROR('Concept(s) Analysis Breakdown'!EE8,0) -> 3992.5 | E14: =IFERROR('Concept(s) Analysis Breakdown'!EE9,0) -> 0 | F14: =IFERROR('Concept(s) Analysis Breakdown'!EE10,0) -> 0 | G14: ='Concept(s) Analysis Breakdown'!EE11 -> 5245.5 | H14: =IFERROR('Concept(s) Analysis Breakdown'!EE12,0) -> 0 | I14: ='Concept(s) Analysis Breakdown'!EE13 -> 5671 | J14: =IFERROR('Concept(s) Analysis Breakdown'!EE14,0) -> 0 | K14: =IFERROR('Concept(s) Analysis Breakdown'!EE15,0) -> 0 | L14: {=AVERAGE(IF(D14:K14>0,D14:K14))} -> 4969.6667 | M14: {=_xlfn.STDEV.S(IF(D14:K14>0,D14:K14))} -> 872.58443
C17: Category-based Time Slot Differences from Best Performing Mix
C18: Column1 | D18: Prime hours | E18: Great times | F18: Good times | G18: Late-night | H18: Early asf | I18: GG EST Mfs | J18: Lol | K18: KeYS | L18: μ | M18: 𝜎
